Workbook

Sheet Read me
A1: IRIS market and revenue model
A2: Version of 24 October 2026. Prepared for the IRIS investor deck (slides 14, 15, A4 and A5).
A4: How to use it
A5: Change inputs on the Inputs sheet only. Blue text = an input. Black = a formula. Green = a link from another sheet.
A6: Yellow cells are open decisions (round size, founder salaries, use of funds) and should be confirmed.
A7: Base and Conservative run side by side: each has its own column on Inputs and its own monthly sheet.
A9: Sheets
A10: Summary: three years for both cases: revenue, costs, operating result, cash, drivers and the market.
A11: Market: total, serviceable and obtainable market, built from IBISWorld's figures.
A12: Inputs: every assumption, with its type (reported, estimate, company decision) and source.
A13: Base and Conservative: 36 months of drivers, revenue, costs and cash.
A15: What the model assumes
... A19: Formatting follows standard financial-model conventions; it can be restyled to match another template.

Sheet Inputs
A1: IRIS market and revenue model: inputs
A2: Blue cells are inputs; change them here and every other sheet recalculates. Yellow cells are open decisions. A$, excluding GST. Month 1 is the month the round closes.
A4: Input | B4: Base | C4: Conservative | D4: Unit | E4: Type | F4: Source or basis
A6: 1. Building work a year, Australia (straight from IBISWorld)
A7: Multi-unit: medium-rise flats and units (4–8 storeys) | B7: 18.9 | C7: same | D7: A$bn a year | E7: Reported | F7: IBISWorld E3019 Multi-Unit Apartment and Townhouse Construction in Australia (2026), products and services segmentation, 2025-26: $18.9bn (30.7%).
A8: Multi-unit: high-rise and super high-rise apartments (9+ storeys) | B8: 14.6 | C8: same | D8: A$bn a year | E8: Reported | F8: IBISWorld E3019 Multi-Unit Apartment and Townhouse Construction in Australia (2026), 2025-26: $14.6bn (23.7%).
A9: Multi-unit: low-rise apartments (1–3 storeys) | B9: 4.2 | C9: same | D9: A$bn a year | E9: Reported | F9: IBISWorld E3019 Multi-Unit Apartment and Townhouse Construction in Australia (2026), 2025-26: $4.2bn (6.9%). Out of scope: mostly jobs under $10M.
A10: Multi-unit: townhouses, other dwellings and conversions | B10: 23.8 | C10: same | D10: A$bn a year | E10: Reported | F10: IBISWorld E3019 Multi-Unit Apartment and Townhouse Construction in Australia (2026), 2025-26: $23.8bn (38.7%). Out of scope: mostly small jobs by house builders.
A11: C&I: factory and industrial buildings | B11: 19.4 | C11: same | D11: A$bn a year | E11: Reported | F11: IBISWorld E3021 Commercial and Industrial Building Construction in Australia (2026), products and services segmentation, 2026-27: $19.4bn (27.4%).
A12: C&I: offices | B12: 16.2 | C12: same | D12: A$bn a year | E12: Reported | F12: IBISWorld E3021 Commercial and Industrial Building Construction in Australia (2026), 2026-27: $16.2bn (22.8%).
A13: C&I: retail buildings | B13: 11.8 | C13: same | D13: A$bn a year | E13: Reported | F13: IBISWorld E3021 Commercial and Industrial Building Construction in Australia (2026), 2026-27: $11.8bn (16.7%).
A14: C&I: entertainment and recreational buildings | B14: 6 | C14: same | D14: A$bn a year | E14: Reported | F14: IBISWorld E3021 Commercial and Industrial Building Construction in Australia (2026), 2026-27: $6.0bn (8.4%).
A15: C&I: hotels | B15: 4.8 | C15: same | D15: A$bn a year | E15: Reported | F15: IBISWorld E3021 Commercial and Industrial Building Construction in Australia (2026), 2026-27: $4.8bn (6.8%).
A16: C&I: other business premises | B16: 12.7 | C16: same | D16: A$bn a year | E16: Reported | F16: IBISWorld E3021 Commercial and Industrial Building Construction in Australia (2026), 2026-27: $12.7bn (17.9%).
A18: 2. Scope, who funds it, and Queensland
A19: Share of C&I building work on jobs of $10M or more | B19: 0.65 | C19: same | D19: % of value | E19: Estimate | F19: Estimate; IBISWorld does not split by job size. Cross-check: the top 50 builders alone started 722 projects worth $43.9bn in 2025, averaging about $61M (Hubexo Construction League, April 2026).
A20: Multi-unit work funded by developers | B20: 0.88 | C20: same | D20: % of value | E20: Reported | F20: IBISWorld E3019 Multi-Unit Apartment and Townhouse Construction in Australia (2026), major markets, 2025-26: large developers and REITs 48.8% plus owners and small developers 39.2%.
A21: C&I work funded by developers | B21: 0.731 | C21: same | D21: % of value | E21: Reported | F21: IBISWorld E3021 Commercial and Industrial Building Construction in Australia (2026), major markets, 2026-27: commercial property developers 59.8% plus industrial property developers 13.3%. End users (23.3%) mostly fund from their own balance sheets.
A22: Queensland share of multi-unit building work | B22: 0.196 | C22: same | D22: % of value | E22: Reported | F22: IBISWorld E3019 Multi-Unit Apartment and Townhouse Construction in Australia (2026), geographic breakdown: Queensland 19.6% of the value of apartment and townhouse work done, 2024-25.
A23: Queensland share of C&I building work | B23: 0.182 | C23: same | D23: % of value | E23: Reported (proxy) | F23: IBISWorld E3021 Commercial and Industrial Building Construction in Australia (2026), geographic breakdown: Queensland has 18.2% of establishments, and its share of work done is below its one-fifth population share. Used as the proxy until ABS state tables are pulled.
A25: 3. From building work to live projects and facilities
A26: Average build period, apartments | B26: 29 | C26: same | D26: months | E26: Measured | F26: ABS average completion time for apartments, FY2025-26: 9.54 quarters, about 29 months (10.03 quarters in Queensland), via The Good Builder citing the ABS data cube, October 2026.
A27: Average build period, C&I jobs of $10M or more | B27: 24 | C27: same | D27: months | E27: Estimate | F27: Estimate. Cross-check: ABS non-residential work yet to be done was $76.4bn at March 2026 against about $70bn of work a year (ABS).
A28: Average contract value, jobs of $10M or more | B28: 40 | C28: same | D28: A$M | E28: Estimate | F28: Estimate. Cross-checks: Brisbane and Gold Coast apartment projects on hold average about $48M (PRD via The Good Builder, September 2026); Qualitas senior construction loans average about $39M (June 2026); the top 50 builders' 2025 starts averaged about $61M (Hubexo).
A29: Construction facility as a share of the build contract | B29: 1 | C29: same | D29: x | E29: Estimate | F29: Estimate. Lenders fund about 60–80% of total development cost (banks 60–70%, non-banks 75–80%: Feasly and Vertex Capital, 2026), and the build is roughly two-thirds of that cost, so the facility is about the size of the build contract.
A30: Contract security held on a live job | B30: 0.05 | C30: same | D30: % of contract | E30: Estimate | F30: Estimate: 5% security is common under AS 4000-style head contracts. Used only for the insurer and surety memo line.
A31: Surety and bank guarantee fee | B31: 0.01 | C31: same | D31: % a year | E31: Reported | F31: Brokers quote 0.5–1.5% a year for surety and 0.5–2% for bank guarantees (BCS Broking, 2026). Memo line only.
A32: Developers' spend on quantity surveying services | B32: 711 | C32: same | D32: A$M a year | E32: Reported | F32: IBISWorld OD5428 Quantity Surveying Services in Australia (2026), major markets, 2025-26: property developers $711.0m (26.7%). Context only.
A34: 4. Pricing
A35: Builder subscription, per project | B35: 3500 | C35: 3500 | D35: A$ a month | E35: Company | F35: Company pricing for builder deployments (slide 10).
A36: Facility fee | B36: 15 | C36: 12.5 | D36: bps a year | E36: Company | F36: Charged on the facility limit, paid by the developer as a condition of the facility. Range tested: 10–20 bps.
A37: Facility fee floor | B37: 3500 | C37: 3500 | D37: A$ a month | E37: Company | F37: Floor so a small facility pays no less than a builder subscription.
A38: Facility fee cap | B38: 10000 | C38: 10000 | D38: A$ a month | E38: Company | F38: Cap so the fee stays proportionate on large facilities (Textura caps its fee for the same reason).
A39: Average facility, first lenders | B39: 35 | C39: 30 | D39: A$M | E39: Estimate | F39: Estimate for South East Queensland facilities. Qualitas senior construction loans average about $39M (June 2026); Brisbane apartment projects on hold average about $35M (PRD, September 2026).
A41: 5. Builder deployments
A42: R&D deployments go live | B42: 3 | C42: 3 | D42: month | E42: Company | F42: Slide 17: two builder deployments live by month 3.
A43: R&D deployments | B43: 2 | C43: 2 | D43: projects | E43: Company | F43: Slide 17.
A44: Builder deployments start paying | B44: 6 | C44: 7 | D44: month | E44: Company | F44: After the position reconciles to the builder's own cost reports.
A45: New paid builder projects a month, Year 1 | B45: 1 | C45: 0.5 | D45: projects a month | E45: Company | F45: Founder-led sales, after the first paid month.
A46: New paid builder projects a month, Year 2 | B46: 1.25 | C46: 0.75 | D46: projects a month | E46: Company | F46: With a commercial lead once the seed round closes.
...

Sheet Summary
A1: IRIS: three-year summary
A2: A$ unless stated. Year 1 starts the month the round closes. Linked from the Base and Conservative sheets.
B4: Base | F4: Conservative
B5: Year 1 | C5: Year 2 | D5: Year 3 | F5: Year 1 | G5: Year 2 | H5: Year 3
A7: Revenue
A8: Builder subscriptions | B8: =Base!$AN$10 -> 119841.43 | C8: =Base!$AO$10 -> 633551.32 | D8: =Base!$AP$10 -> 1223858.7 | F8: =Conservative!$AN$10 -> 65515.583 | G8: =Conservative!$AO$10 -> 345890.6 | H8: =Conservative!$AP$10 -> 673983.78
A9: Facility fees (developer-paid, lender condition) | B9: =Base!$AN$18 -> 3281.25 | C9: =Base!$AO$18 -> 328125 | D9: =Base!$AP$18 -> 1391250 | F9: =Conservative!$AN$18 -> 0 | G9: =Conservative!$AO$18 -> 49000 | H9: =Conservative!$AP$18 -> 397250
A10: Total revenue | B10: =Base!$AN$20 -> 123122.68 | C10: =Base!$AO$20 -> 961676.32 | D10: =Base!$AP$20 -> 2615108.7 | F10: =Conservative!$AN$20 -> 65515.583 | G10: =Conservative!$AO$20 -> 394890.6 | H10: =Conservative!$AP$20 -> 1071233.8
A12: Costs
A13: People | B13: =Base!$AN$25+Base!$AN$26 -> 313600 | C13: =Base!$AO$25+Base!$AO$26 -> 728000 | D13: =Base!$AP$25+Base!$AP$26 -> 1304800 | F13: =Conservative!$AN$25+Conservative!$AN$26 -> 313600 | G13: =Conservative!$AO$25+Conservative!$AO$26 -> 529200 | H13: =Conservative!$AP$25+Conservative!$AP$26 -> 1002400
A14: Platform build, cloud and security | B14: =Base!$AN$27+Base!$AN$28+Base!$AN$29 -> 318148.56 | C14: =Base!$AO$27+Base!$AO$28+Base!$AO$29 -> 130402.2 | D14: =Base!$AP$27+Base!$AP$28+Base!$AP$29 -> 192151.09 | F14: =Conservative!$AN$27+Conservative!$AN$28+Conservative!$AN$29 -> 317343.75 | G14: =Conservative!$AO$27+Conservative!$AO$28+Conservative!$AO$29 -> 94565.177 | H14: =Conservative!$AP$27+Conservative!$AP$28+Conservative!$AP$29 -> 133213.36
A15: Sales, legal and insurance | B15: =Base!$AN$31+Base!$AN$32+Base!$AN$30 -> 80000 | C15: =Base!$AO$31+Base!$AO$32+Base!$AO$30 -> 150000 | D15: =Base!$AP$31+Base!$AP$32+Base!$AP$30 -> 255000 | F15: =Conservative!$AN$31+Conservative!$AN$32+Conservative!$AN$30 -> 80000 | G15: =Conservative!$AO$31+Conservative!$AO$32+Conservative!$AO$30 -> 130000 | H15: =Conservative!$AP$31+Conservative!$AP$32+Conservative!$AP$30 -> 205000
A16: Contingency | B16: =Base!$AN$33 -> 36000 | C16: =Base!$AO$33 -> 50420.11 | D16: =Base!$AP$33 -> 87597.554 | F16: =Conservative!$AN$33 -> 36000 | G16: =Conservative!$AO$33 -> 37688.259 | H16: =Conservative!$AP$33 -> 67030.668
A17: Total costs | B17: =Base!$AN$34 -> 747748.56 | C17: =Base!$AO$34 -> 1058822.3 | D17: =Base!$AP$34 -> 1839548.6 | F17: =Conservative!$AN$34 -> 746943.75 | G17: =Conservative!$AO$34 -> 791453.44 | H17: =Conservative!$AP$34 -> 1407644
A19: Result and cash
A20: Operating result | B20: =Base!$AN$36 -> -624625.88 | C20: =Base!$AO$36 -> -97145.994 | D20: =Base!$AP$36 -> 775560.04 | F20: =Conservative!$AN$36 -> -681428.16 | G20: =Conservative!$AO$36 -> -396562.84 | H20: =Conservative!$AP$36 -> -336410.25
A21: Cash at year end, before the seed round | B21: =Base!$AN$40 -> 125374.12 | C21: =Base!$AO$40 -> 28228.128 | D21: =Base!$AP$40 -> 803788.16 | F21: =Conservative!$AN$40 -> 68571.835 | G21: =Conservative!$AO$40 -> -327991 | H21: =Conservative!$AP$40 -> -664401.25
A22: Cash at year end, after the seed round | B22: =Base!$AN$42 -> 125374.12 | C22: =Base!$AO$42 -> 3028228.1 | D22: =Base!$AP$42 -> 3803788.2 | F22: =Conservative!$AN$42 -> 68571.835 | G22: =Conservative!$AO$42 -> 2672009 | H22: =Conservative!$AP$42 -> 2335598.7
A24: Drivers at year end
A25: Paid builder projects | B25: =Base!$AN$9 -> 7.7349454 | C25: =Base!$AO$9 -> 21.05803 | D25: =Base!$AP$9 -> 35.707788 | F25: =Conservative!$AN$9 -> 4.2098217 | G25: =Conservative!$AO$9 -> 11.37664 | H25: =Conservative!$AP$9 -> 19.691604
A26: Facilities under the condition | B26: =Base!$AN$16 -> 0.75 | C26: =Base!$AO$16 -> 12.75 | D26: =Base!$AP$16 -> 40.5 | F26: =Conservative!$AN$16 -> 0 | G26: =Conservative!$AO$16 -> 3.5 | H26: =Conservative!$AP$16 -> 16.5
A27: Lenders with the condition | B27: =Base!$AN$13 -> 1 | C27: =Base!$AO$13 -> 2 | D27: =Base!$AP$13 -> 4 | F27: =Conservative!$AN$13 -> 0 | G27: =Conservative!$AO$13 -> 1 | H27: =Conservative!$AP$13 -> 3
A28: Team | B28: =Base!$AN$24 -> 2 | C28: =Base!$AO$24 -> 6 | D28: =Base!$AP$24 -> 9 | F28: =Conservative!$AN$24 -> 2 | G28: =Conservative!$AO$24 -> 5 | H28: =Conservative!$AP$24 -> 7
A29: Annualised revenue at year end | B29: =Base!$AN$21 -> 364242.71 | C29: =Base!$AO$21 -> 1553812.2 | D29: =Base!$AP$21 -> 3625977.1 | F29: =Conservative!$AN$21 -> 176812.51 | G29: =Conservative!$AO$21 -> 624818.89 | H29: =Conservative!$AP$21 -> 1520047.4
A32: Funding check
A33: Lowest cash before the seed round | B33: =MIN(Base!$C$40:$AL$40) -> 4574.5543 | F33: =MIN(Conservative!$C$40:$AL$40) -> -664401.25
A34: First month cash runs out without the seed (99 = never) | B34: =MIN(Base!$C$43:$AL$43) -> 99 | F34: =MIN(Conservative!$C$43:$AL$43) -> 15
A35: Lowest cash after the seed round | B35: =MIN(Base!$C$42:$AL$42) -> 107387.41 | F35: =MIN(Conservative!$C$42:$AL$42) -> -55757.351
A38: Market (from the Market sheet)
A39: Total market (TAM), Australia, A$M a year | B39: =Market!$B$44 -> 244.16357
A40: Serviceable market (SAM), Queensland, A$M a year | B40: =Market!$B$50 -> 46.076691
A41: Obtainable (SOM), month-36 annualised revenue, A$M | B41: =Market!$B$51 -> 3.6259771
A42: Live projects in scope, Australia | B42: =Market!$B$33 -> 4328.2083
A43: Live projects in scope, Queensland | B43: =Market!$B$49 -> 816.06933
A46: What moves the result (base case)
A47: Year 3 facility fees for each basis point of fee | B47: =Base!$AP$18/Inputs!$B$36 -> 92750
A48: Annualised facility fees per lender at month 36 | B48: =IF(Base!$AL$13=0,0,Base!$AL$18*12/Base!$AL$13) -> 531562.5
A49: Annualised revenue per paid builder project | B49: =Inputs!$B$35*12 -> 42000
A50: Annualised fee per facility at month 36 | B50: =Base!$AL$17*12 -> 52500

Sheet Market
A1: Market: total, serviceable and obtainable
A2: Built from IBISWorld's figures for the two industries IRIS serves. Green cells link to Inputs; black cells are formulas. Change inputs on the Inputs sheet.
A4: Line | B4: Value | C4: Unit | D4: How it is worked out
A6: A. Building work a year in IRIS's scope (IBISWorld)
A7: Medium-rise flats and units | B7: =Inputs!$B$7 -> 18.9 | C7: A$bn | D7: IBISWorld E3019, 2025-26. In scope.
A8: High-rise and super high-rise apartments | B8: =Inputs!$B$8 -> 14.6 | C8: A$bn | D8: IBISWorld E3019, 2025-26. In scope.
A9: Low-rise apartments | B9: =Inputs!$B$9 -> 4.2 | C9: A$bn | D9: IBISWorld E3019. Out of scope: mostly under $10M a job.
A10: Townhouses, other dwellings and conversions | B10: =Inputs!$B$10 -> 23.8 | C10: A$bn | D10: IBISWorld E3019. Out of scope.
A11: Multi-unit residential, all segments | B11: =SUM(B7:B9)+B10 -> 61.5 | C11: A$bn | D11: IBISWorld reports $61.4bn; segments sum to $61.5bn through rounding.
A12: Commercial and industrial building, all segments | B12: =SUM(Inputs!$B$11:$B$16) -> 70.9 | C12: A$bn | D12: IBISWorld E3021, 2026-27: $70.9bn.
A13: Share of C&I work on jobs of $10M or more | B13: =Inputs!$B$19 -> 0.65 | C13: % | D13: See Inputs.
A14: Multi-unit work in scope | B14: =$B$7+$B$8 -> 33.5 | C14: A$bn | D14: Medium-rise plus high-rise.
A15: C&I work in scope | B15: =$B$12*$B$13 -> 46.085 | C15: A$bn | D15: All C&I segments, jobs of $10M or more.
A16: Building work in scope, Australia | B16: =$B$14+$B$15 -> 79.585 | C16: A$bn a year
A18: B. From work a year to value under construction
A19: Average build period, apartments | B19: =Inputs!$B$26 -> 29 | C19: months | D19: ABS, FY2025-26.
A20: Average build period, C&I | B20: =Inputs!$B$27 -> 24 | C20: months | D20: See Inputs.
A21: Multi-unit value under construction | B21: =$B$14*$B$19/12 -> 80.958333 | C21: A$bn | D21: Work a year × build period: each job is live for its build period.
A22: C&I value under construction | B22: =$B$15*$B$20/12 -> 92.17 | C22: A$bn
A23: Value under construction in scope, Australia | B23: =$B$21+$B$22 -> 173.12833 | C23: A$bn
A25: C. Who funds it (IBISWorld major markets)
A26: Multi-unit work funded by developers | B26: =Inputs!$B$20 -> 0.88 | C26: % | D26: IBISWorld E3019.
A27: C&I work funded by developers | B27: =Inputs!$B$21 -> 0.731 | C27: % | D27: IBISWorld E3021.
A28: Developer-funded value under construction | B28: =$B$21*$B$26+$B$22*$B$27 -> 138.6196 | C28: A$bn | D28: Where a construction lender can make IRIS a condition of the facility.
A29: Other value under construction | B29: =$B$23-$B$28 -> 34.50873 | C29: A$bn | D29: End users, government and other owners: no construction facility to condition, so builders pay.
A31: D. Live projects and price per project
A32: Average contract value, jobs of $10M or more | B32: =Inputs!$B$28 -> 40 | C32: A$M | D32: See Inputs.
A33: Live projects in scope, Australia | B33: =IF($B$32=0,0,$B$23*1000/$B$32) -> 4328.2083 | C33: projects | D33: Value under construction ÷ average contract value.
A34: of which developer-funded (facility fee) | B34: =IF($B$32=0,0,$B$28*1000/$B$32) -> 3465.4901 | C34: projects
A35: of which other (builder subscription) | B35: =$B$33-$B$34 -> 862.71825 | C35: projects
A36: Facility as a share of the build contract | B36: =Inputs!$B$29 -> 1 | C36: x | D36: See Inputs.
A37: Facility fee | B37: =Inputs!$B$36 -> 15 | C37: bps a year | D37: Base case.
A38: Facility fee per facility | B38: =MIN(MAX($B$32*$B$36*1000000*$B$37/10000,Inputs!$B$37*12),Inputs!$B$38*12) -> 60000 | C38: A$ a year | D38: Average facility × fee, within the floor and cap.
A39: Builder subscription per project | B39: =Inputs!$B$35*12 -> 42000 | C39: A$ a year
A41: E. Market, A$ millions a year
A42: Facility fees on every developer-funded project | B42: =$B$34*$B$38/1000000 -> 207.92941 | C42: A$M a year
A43: Builder subscriptions on every other project | B43: =$B$35*$B$39/1000000 -> 36.234167 | C43: A$M a year
A44: Total market (TAM): Australia, every project in scope | B44: =$B$42+$B$43 -> 244.16357 | C44: A$M a year | D44: Every live job of $10M or more on IRIS.
A45: Queensland share of multi-unit work | B45: =Inputs!$B$22 -> 0.196 | C45: % | D45: IBISWorld E3019.
A46: Queensland share of C&I work | B46: =Inputs!$B$23 -> 0.182 | C46: % | D46: See Inputs.
...

Sheet Base
A1: Base case: monthly
A2: Monthly drivers, revenue, costs and cash. Formulas only; inputs are on the Inputs sheet. A$.
A3: Month | C3: 1 | D3: =C3+1 -> 2 | E3: =D3+1 -> 3 | F3: =E3+1 -> 4 | G3: =F3+1 -> 5 | H3: =G3+1 -> 6 | I3: =H3+1 -> 7 | J3: =I3+1 -> 8 | K3: =J3+1 -> 9 | ... AL3: =AK3+1 -> 36 | AN3: Year 1 | AO3: Year 2 | AP3: Year 3
A4: Year | C4: =ROUNDUP(C3/12,0) -> 1 | D4: =ROUNDUP(D3/12,0) -> 1 | E4: =ROUNDUP(E3/12,0) -> 1 | F4: =ROUNDUP(F3/12,0) -> 1 | G4: =ROUNDUP(G3/12,0) -> 1 | H4: =ROUNDUP(H3/12,0) -> 1 | I4: =ROUNDUP(I3/12,0) -> 1 | J4: =ROUNDUP(J3/12,0) -> 1 | ... AL4: =ROUNDUP(AL3/12,0) -> 3 | AN4: total or year end | AO4: total or year end | AP4: total or year end
A6: Builder deployments
A7: R&D deployments live (unpaid) | B7: projects | C7: =IF(AND(C$3>=Inputs!$B$42,C$3<Inputs!$B$44),Inputs!$B$43,0) -> 0 | D7: =IF(AND(D$3>=Inputs!$B$42,D$3<Inputs!$B$44),Inputs!$B$43,0) -> 0 | E7: =IF(AND(E$3>=Inputs!$B$42,E$3<Inputs!$B$44),Inputs!$B$43,0) -> 2 | F7: =IF(AND(F$3>=Inputs!$B$42,F$3<Inputs!$B$44),Inputs!$B$43,0) -> 2 | G7: =IF(AND(G$3>=Inputs!$B$42,G$3<Inputs!$B$44),Inputs!$B$43,0) -> 2 | H7: =IF(AND(H$3>=Inputs!$B$42,H$3<Inputs!$B$44),Inputs!$B$43,0) -> 0 | I7: =IF(AND(I$3>=Inputs!$B$42,I$3<Inputs!$B$44),Inputs!$B$43,0) -> 0 | J7: =IF(AND(J$3>=Inputs!$B$42,J$3<Inputs!$B$44),Inputs!$B$43,0) -> 0 | ... AL7: =IF(AND(AL$3>=Inputs!$B$42,AL$3<Inputs!$B$44),Inputs!$B$43,0) -> 0 | AN7: =INDEX($C7:$AL7,1,12) -> 0 | AO7: =INDEX($C7:$AL7,1,24) -> 0 | AP7: =INDEX($C7:$AL7,1,36) -> 0
A8: New paid builder projects | B8: projects | C8: =IF(C$3<=Inputs!$B$44,0,CHOOSE(C$4,Inputs!$B$45,Inputs!$B$46,Inputs!$B$47)) -> 0 | D8: =IF(D$3<=Inputs!$B$44,0,CHOOSE(D$4,Inputs!$B$45,Inputs!$B$46,Inputs!$B$47)) -> 0 | E8: =IF(E$3<=Inputs!$B$44,0,CHOOSE(E$4,Inputs!$B$45,Inputs!$B$46,Inputs!$B$47)) -> 0 | F8: =IF(F$3<=Inputs!$B$44,0,CHOOSE(F$4,Inputs!$B$45,Inputs!$B$46,Inputs!$B$47)) -> 0 | G8: =IF(G$3<=Inputs!$B$44,0,CHOOSE(G$4,Inputs!$B$45,Inputs!$B$46,Inputs!$B$47)) -> 0 | H8: =IF(H$3<=Inputs!$B$44,0,CHOOSE(H$4,Inputs!$B$45,Inputs!$B$46,Inputs!$B$47)) -> 0 | I8: =IF(I$3<=Inputs!$B$44,0,CHOOSE(I$4,Inputs!$B$45,Inputs!$B$46,Inputs!$B$47)) -> 1 | J8: =IF(J$3<=Inputs!$B$44,0,CHOOSE(J$4,Inputs!$B$45,Inputs!$B$46,Inputs!$B$47)) -> 1 | ... AL8: =IF(AL$3<=Inputs!$B$44,0,CHOOSE(AL$4,Inputs!$B$45,Inputs!$B$46,Inputs!$B$47)) -> 1.5 | AN8: =SUMIF($C$4:$AL$4,1,$C8:$AL8) -> 6 | AO8: =SUMIF($C$4:$AL$4,2,$C8:$AL8) -> 15 | AP8: =SUMIF($C$4:$AL$4,3,$C8:$AL8) -> 18
A9: Paid builder projects, end of month | B9: projects | C9: =IF(C$3<Inputs!$B$44,0,IF(C$3=Inputs!$B$44,Inputs!$B$43,0*(1-Inputs!$B$48)+C8)) -> 0 | D9: =IF(D$3<Inputs!$B$44,0,IF(D$3=Inputs!$B$44,Inputs!$B$43,C9*(1-Inputs!$B$48)+D8)) -> 0 | E9: =IF(E$3<Inputs!$B$44,0,IF(E$3=Inputs!$B$44,Inputs!$B$43,D9*(1-Inputs!$B$48)+E8)) -> 0 | F9: =IF(F$3<Inputs!$B$44,0,IF(F$3=Inputs!$B$44,Inputs!$B$43,E9*(1-Inputs!$B$48)+F8)) -> 0 | G9: =IF(G$3<Inputs!$B$44,0,IF(G$3=Inputs!$B$44,Inputs!$B$43,F9*(1-Inputs!$B$48)+G8)) -> 0 | H9: =IF(H$3<Inputs!$B$44,0,IF(H$3=Inputs!$B$44,Inputs!$B$43,G9*(1-Inputs!$B$48)+H8)) -> 2 | I9: =IF(I$3<Inputs!$B$44,0,IF(I$3=Inputs!$B$44,Inputs!$B$43,H9*(1-Inputs!$B$48)+I8)) -> 2.98 | J9: =IF(J$3<Inputs!$B$44,0,IF(J$3=Inputs!$B$44,Inputs!$B$43,I9*(1-Inputs!$B$48)+J8)) -> 3.9502 | K9: =IF(K$3<Inputs!$B$44,0,IF(K$3=Inputs!$B$44,Inputs!$B$43,J9*(1-Inputs!$B$48)+K8)) -> 4.910698 | ... AL9: =IF(AL$3<Inputs!$B$44,0,IF(AL$3=Inputs!$B$44,Inputs!$B$43,AK9*(1-Inputs!$B$48)+AL8)) -> 35.707788 | AN9: =INDEX($C9:$AL9,1,12) -> 7.7349454 | AO9: =INDEX($C9:$AL9,1,24) -> 21.05803 | AP9: =INDEX($C9:$AL9,1,36) -> 35.707788
A10: Builder subscription revenue | B10: A$ | C10: =C9*Inputs!$B$35 -> 0 | D10: =D9*Inputs!$B$35 -> 0 | E10: =E9*Inputs!$B$35 -> 0 | F10: =F9*Inputs!$B$35 -> 0 | G10: =G9*Inputs!$B$35 -> 0 | H10: =H9*Inputs!$B$35 -> 7000 | I10: =I9*Inputs!$B$35 -> 10430 | J10: =J9*Inputs!$B$35 -> 13825.7 | ... AL10: =AL9*Inputs!$B$35 -> 124977.26 | AN10: =SUMIF($C$4:$AL$4,1,$C10:$AL10) -> 119841.43 | AO10: =SUMIF($C$4:$AL$4,2,$C10:$AL10) -> 633551.32 | AP10: =SUMIF($C$4:$AL$4,3,$C10:$AL10) -> 1223858.7
A12: Lender mandates
A13: Lenders with the condition | B13: lenders | C13: =COUNTIF(Inputs!$B$51:$B$55,"<="&C$3) -> 0 | D13: =COUNTIF(Inputs!$B$51:$B$55,"<="&D$3) -> 0 | E13: =COUNTIF(Inputs!$B$51:$B$55,"<="&E$3) -> 0 | F13: =COUNTIF(Inputs!$B$51:$B$55,"<="&F$3) -> 0 | G13: =COUNTIF(Inputs!$B$51:$B$55,"<="&G$3) -> 0 | H13: =COUNTIF(Inputs!$B$51:$B$55,"<="&H$3) -> 0 | I13: =COUNTIF(Inputs!$B$51:$B$55,"<="&I$3) -> 0 | J13: =COUNTIF(Inputs!$B$51:$B$55,"<="&J$3) -> 0 | ... AL13: =COUNTIF(Inputs!$B$51:$B$55,"<="&AL$3) -> 4 | AN13: =INDEX($C13:$AL13,1,12) -> 1 | AO13: =INDEX($C13:$AL13,1,24) -> 2 | AP13: =INDEX($C13:$AL13,1,36) -> 4
A14: New facilities under the condition | B14: facilities | C14: =C13*Inputs!$B$56 -> 0 | D14: =D13*Inputs!$B$56 -> 0 | E14: =E13*Inputs!$B$56 -> 0 | F14: =F13*Inputs!$B$56 -> 0 | G14: =G13*Inputs!$B$56 -> 0 | H14: =H13*Inputs!$B$56 -> 0 | I14: =I13*Inputs!$B$56 -> 0 | J14: =J13*Inputs!$B$56 -> 0 | ... AL14: =AL13*Inputs!$B$56 -> 3 | AN14: =SUMIF($C$4:$AL$4,1,$C14:$AL14) -> 0.75 | AO14: =SUMIF($C$4:$AL$4,2,$C14:$AL14) -> 12 | AP14: =SUMIF($C$4:$AL$4,3,$C14:$AL14) -> 28.5
A15: Facilities completing | B15: facilities | C15: =IF(C$3>Inputs!$B$57,INDEX($C$14:$AL$14,1,C$3-Inputs!$B$57),0) -> 0 | D15: =IF(D$3>Inputs!$B$57,INDEX($C$14:$AL$14,1,D$3-Inputs!$B$57),0) -> 0 | E15: =IF(E$3>Inputs!$B$57,INDEX($C$14:$AL$14,1,E$3-Inputs!$B$57),0) -> 0 | F15: =IF(F$3>Inputs!$B$57,INDEX($C$14:$AL$14,1,F$3-Inputs!$B$57),0) -> 0 | G15: =IF(G$3>Inputs!$B$57,INDEX($C$14:$AL$14,1,G$3-Inputs!$B$57),0) -> 0 | H15: =IF(H$3>Inputs!$B$57,INDEX($C$14:$AL$14,1,H$3-Inputs!$B$57),0) -> 0 | I15: =IF(I$3>Inputs!$B$57,INDEX($C$14:$AL$14,1,I$3-Inputs!$B$57),0) -> 0 | J15: =IF(J$3>Inputs!$B$57,INDEX($C$14:$AL$14,1,J$3-Inputs!$B$57),0) -> 0 | ... AL15: =IF(AL$3>Inputs!$B$57,INDEX($C$14:$AL$14,1,AL$3-Inputs!$B$57),0) -> 0.75 | AN15: =SUMIF($C$4:$AL$4,1,$C15:$AL15) -> 0 | AO15: =SUMIF($C$4:$AL$4,2,$C15:$AL15) -> 0 | AP15: =SUMIF($C$4:$AL$4,3,$C15:$AL15) -> 0.75
A16: Facilities under the condition, end of month | B16: facilities | C16: =C14-C15 -> 0 | D16: =C16+D14-D15 -> 0 | E16: =D16+E14-E15 -> 0 | F16: =E16+F14-F15 -> 0 | G16: =F16+G14-G15 -> 0 | H16: =G16+H14-H15 -> 0 | I16: =H16+I14-I15 -> 0 | J16: =I16+J14-J15 -> 0 | K16: =J16+K14-K15 -> 0 | ... AL16: =AK16+AL14-AL15 -> 40.5 | AN16: =INDEX($C16:$AL16,1,12) -> 0.75 | AO16: =INDEX($C16:$AL16,1,24) -> 12.75 | AP16: =INDEX($C16:$AL16,1,36) -> 40.5
A17: Fee per facility | B17: A$ a month | C17: =MIN(MAX(Inputs!$B$39*1000000*Inputs!$B$36/10000/12,Inputs!$B$37),Inputs!$B$38) -> 4375 | D17: =MIN(MAX(Inputs!$B$39*1000000*Inputs!$B$36/10000/12,Inputs!$B$37),Inputs!$B$38) -> 4375 | E17: =MIN(MAX(Inputs!$B$39*1000000*Inputs!$B$36/10000/12,Inputs!$B$37),Inputs!$B$38) -> 4375 | F17: =MIN(MAX(Inputs!$B$39*1000000*Inputs!$B$36/10000/12,Inputs!$B$37),Inputs!$B$38) -> 4375 | G17: =MIN(MAX(Inputs!$B$39*1000000*Inputs!$B$36/10000/12,Inputs!$B$37),Inputs!$B$38) -> 4375 | H17: =MIN(MAX(Inputs!$B$39*1000000*Inputs!$B$36/10000/12,Inputs!$B$37),Inputs!$B$38) -> 4375 | I17: =MIN(MAX(Inputs!$B$39*1000000*Inputs!$B$36/10000/12,Inputs!$B$37),Inputs!$B$38) -> 4375 | J17: =MIN(MAX(Inputs!$B$39*1000000*Inputs!$B$36/10000/12,Inputs!$B$37),Inputs!$B$38) -> 4375 | ... AL17: =MIN(MAX(Inputs!$B$39*1000000*Inputs!$B$36/10000/12,Inputs!$B$37),Inputs!$B$38) -> 4375 | AN17: =INDEX($C17:$AL17,1,12) -> 4375 | AO17: =INDEX($C17:$AL17,1,24) -> 4375 | AP17: =INDEX($C17:$AL17,1,36) -> 4375
A18: Facility fee revenue | B18: A$ | C18: =C16*C17 -> 0 | D18: =D16*D17 -> 0 | E18: =E16*E17 -> 0 | F18: =F16*F17 -> 0 | G18: =G16*G17 -> 0 | H18: =H16*H17 -> 0 | I18: =I16*I17 -> 0 | J18: =J16*J17 -> 0 | ... AL18: =AL16*AL17 -> 177187.5 | AN18: =SUMIF($C$4:$AL$4,1,$C18:$AL18) -> 3281.25 | AO18: =SUMIF($C$4:$AL$4,2,$C18:$AL18) -> 328125 | AP18: =SUMIF($C$4:$AL$4,3,$C18:$AL18) -> 1391250
A20: Total revenue | B20: A$ | C20: =C10+C18 -> 0 | D20: =D10+D18 -> 0 | E20: =E10+E18 -> 0 | F20: =F10+F18 -> 0 | G20: =G10+G18 -> 0 | H20: =H10+H18 -> 7000 | I20: =I10+I18 -> 10430 | J20: =J10+J18 -> 13825.7 | ... AL20: =AL10+AL18 -> 302164.76 | AN20: =SUMIF($C$4:$AL$4,1,$C20:$AL20) -> 123122.68 | AO20: =SUMIF($C$4:$AL$4,2,$C20:$AL20) -> 961676.32 | AP20: =SUMIF($C$4:$AL$4,3,$C20:$AL20) -> 2615108.7
A21: Annualised revenue (month × 12) | B21: A$ | C21: =C20*12 -> 0 | D21: =D20*12 -> 0 | E21: =E20*12 -> 0 | F21: =F20*12 -> 0 | G21: =G20*12 -> 0 | H21: =H20*12 -> 84000 | I21: =I20*12 -> 125160 | J21: =J20*12 -> 165908.4 | ... AL21: =AL20*12 -> 3625977.1 | AN21: =INDEX($C21:$AL21,1,12) -> 364242.71 | AO21: =INDEX($C21:$AL21,1,24) -> 1553812.2 | AP21: =INDEX($C21:$AL21,1,36) -> 3625977.1
A23: Team and costs
A24: Team, end of month | B24: people | C24: =Inputs!$B$60+COUNTIF(Inputs!$C$66:$C$72,"<="&C$3) -> 2 | D24: =Inputs!$B$60+COUNTIF(Inputs!$C$66:$C$72,"<="&D$3) -> 2 | E24: =Inputs!$B$60+COUNTIF(Inputs!$C$66:$C$72,"<="&E$3) -> 2 | F24: =Inputs!$B$60+COUNTIF(Inputs!$C$66:$C$72,"<="&F$3) -> 2 | G24: =Inputs!$B$60+COUNTIF(Inputs!$C$66:$C$72,"<="&G$3) -> 2 | H24: =Inputs!$B$60+COUNTIF(Inputs!$C$66:$C$72,"<="&H$3) -> 2 | I24: =Inputs!$B$60+COUNTIF(Inputs!$C$66:$C$72,"<="&I$3) -> 2 | J24: =Inputs!$B$60+COUNTIF(Inputs!$C$66:$C$72,"<="&J$3) -> 2 | ... AL24: =Inputs!$B$60+COUNTIF(Inputs!$C$66:$C$72,"<="&AL$3) -> 9 | AN24: =INDEX($C24:$AL24,1,12) -> 2 | AO24: =INDEX($C24:$AL24,1,24) -> 6 | AP24: =INDEX($C24:$AL24,1,36) -> 9
A25: Founders | B25: A$ | C25: =Inputs!$B$60*Inputs!$B$61/12*(1+Inputs!$B$62) -> 26133.333 | D25: =Inputs!$B$60*Inputs!$B$61/12*(1+Inputs!$B$62) -> 26133.333 | E25: =Inputs!$B$60*Inputs!$B$61/12*(1+Inputs!$B$62) -> 26133.333 | F25: =Inputs!$B$60*Inputs!$B$61/12*(1+Inputs!$B$62) -> 26133.333 | G25: =Inputs!$B$60*Inputs!$B$61/12*(1+Inputs!$B$62) -> 26133.333 | H25: =Inputs!$B$60*Inputs!$B$61/12*(1+Inputs!$B$62) -> 26133.333 | I25: =Inputs!$B$60*Inputs!$B$61/12*(1+Inputs!$B$62) -> 26133.333 | J25: =Inputs!$B$60*Inputs!$B$61/12*(1+Inputs!$B$62) -> 26133.333 | ... AL25: =Inputs!$B$60*Inputs!$B$61/12*(1+Inputs!$B$62) -> 26133.333 | AN25: =SUMIF($C$4:$AL$4,1,$C25:$AL25) -> 313600 | AO25: =SUMIF($C$4:$AL$4,2,$C25:$AL25) -> 313600 | AP25: =SUMIF($C$4:$AL$4,3,$C25:$AL25) -> 313600
A26: Hires | B26: A$ | C26: =SUMPRODUCT((Inputs!$C$66:$C$72<=C$3)*Inputs!$B$66:$B$72)/12*(1+Inputs!$B$62) -> 0 | D26: =SUMPRODUCT((Inputs!$C$66:$C$72<=D$3)*Inputs!$B$66:$B$72)/12*(1+Inputs!$B$62) -> 0 | E26: =SUMPRODUCT((Inputs!$C$66:$C$72<=E$3)*Inputs!$B$66:$B$72)/12*(1+Inputs!$B$62) -> 0 | F26: =SUMPRODUCT((Inputs!$C$66:$C$72<=F$3)*Inputs!$B$66:$B$72)/12*(1+Inputs!$B$62) -> 0 | G26: =SUMPRODUCT((Inputs!$C$66:$C$72<=G$3)*Inputs!$B$66:$B$72)/12*(1+Inputs!$B$62) -> 0 | H26: =SUMPRODUCT((Inputs!$C$66:$C$72<=H$3)*Inputs!$B$66:$B$72)/12*(1+Inputs!$B$62) -> 0 | I26: =SUMPRODUCT((Inputs!$C$66:$C$72<=I$3)*Inputs!$B$66:$B$72)/12*(1+Inputs!$B$62) -> 0 | J26: =SUMPRODUCT((Inputs!$C$66:$C$72<=J$3)*Inputs!$B$66:$B$72)/12*(1+Inputs!$B$62) -> 0 | ... AL26: =SUMPRODUCT((Inputs!$C$66:$C$72<=AL$3)*Inputs!$B$66:$B$72)/12*(1+Inputs!$B$62) -> 91466.667 | AN26: =SUMIF($C$4:$AL$4,1,$C26:$AL26) -> 0 | AO26: =SUMIF($C$4:$AL$4,2,$C26:$AL26) -> 414400 | AP26: =SUMIF($C$4:$AL$4,3,$C26:$AL26) -> 991200
A27: Platform build and contract engineering | B27: A$ | C27: =CHOOSE(C$4,Inputs!$B$75,Inputs!$B$76,Inputs!$B$77)/12 -> 21666.667 | D27: =CHOOSE(D$4,Inputs!$B$75,Inputs!$B$76,Inputs!$B$77)/12 -> 21666.667 | E27: =CHOOSE(E$4,Inputs!$B$75,Inputs!$B$76,Inputs!$B$77)/12 -> 21666.667 | F27: =CHOOSE(F$4,Inputs!$B$75,Inputs!$B$76,Inputs!$B$77)/12 -> 21666.667 | G27: =CHOOSE(G$4,Inputs!$B$75,Inputs!$B$76,Inputs!$B$77)/12 -> 21666.667 | H27: =CHOOSE(H$4,Inputs!$B$75,Inputs!$B$76,Inputs!$B$77)/12 -> 21666.667 | I27: =CHOOSE(I$4,Inputs!$B$75,Inputs!$B$76,Inputs!$B$77)/12 -> 21666.667 | J27: =CHOOSE(J$4,Inputs!$B$75,Inputs!$B$76,Inputs!$B$77)/12 -> 21666.667 | ... AL27: =CHOOSE(AL$4,Inputs!$B$75,Inputs!$B$76,Inputs!$B$77)/12 -> 5000 | AN27: =SUMIF($C$4:$AL$4,1,$C27:$AL27) -> 260000 | AO27: =SUMIF($C$4:$AL$4,2,$C27:$AL27) -> 60000 | AP27: =SUMIF($C$4:$AL$4,3,$C27:$AL27) -> 60000
A28: Cloud, models and tools | B28: A$ | C28: =Inputs!$B$78+(C7+C9+C16)*Inputs!$B$79 -> 1000 | D28: =Inputs!$B$78+(D7+D9+D16)*Inputs!$B$79 -> 1000 | E28: =Inputs!$B$78+(E7+E9+E16)*Inputs!$B$79 -> 1300 | F28: =Inputs!$B$78+(F7+F9+F16)*Inputs!$B$79 -> 1300 | G28: =Inputs!$B$78+(G7+G9+G16)*Inputs!$B$79 -> 1300 | H28: =Inputs!$B$78+(H7+H9+H16)*Inputs!$B$79 -> 1300 | I28: =Inputs!$B$78+(I7+I9+I16)*Inputs!$B$79 -> 1447 | J28: =Inputs!$B$78+(J7+J9+J16)*Inputs!$B$79 -> 1592.53 | ... AL28: =Inputs!$B$78+(AL7+AL9+AL16)*Inputs!$B$79 -> 12431.168 | AN28: =SUMIF($C$4:$AL$4,1,$C28:$AL28) -> 18148.561 | AO28: =SUMIF($C$4:$AL$4,2,$C28:$AL28) -> 50402.199 | AP28: =SUMIF($C$4:$AL$4,3,$C28:$AL28) -> 112151.09
A29: Security certification and audits | B29: A$ | C29: =CHOOSE(C$4,Inputs!$B$80,Inputs!$B$81,Inputs!$B$81)/12 -> 3333.3333 | D29: =CHOOSE(D$4,Inputs!$B$80,Inputs!$B$81,Inputs!$B$81)/12 -> 3333.3333 | E29: =CHOOSE(E$4,Inputs!$B$80,Inputs!$B$81,Inputs!$B$81)/12 -> 3333.3333 | F29: =CHOOSE(F$4,Inputs!$B$80,Inputs!$B$81,Inputs!$B$81)/12 -> 3333.3333 | G29: =CHOOSE(G$4,Inputs!$B$80,Inputs!$B$81,Inputs!$B$81)/12 -> 3333.3333 | H29: =CHOOSE(H$4,Inputs!$B$80,Inputs!$B$81,Inputs!$B$81)/12 -> 3333.3333 | I29: =CHOOSE(I$4,Inputs!$B$80,Inputs!$B$81,Inputs!$B$81)/12 -> 3333.3333 | J29: =CHOOSE(J$4,Inputs!$B$80,Inputs!$B$81,Inputs!$B$81)/12 -> 3333.3333 | ... AL29: =CHOOSE(AL$4,Inputs!$B$80,Inputs!$B$81,Inputs!$B$81)/12 -> 1666.6667 | AN29: =SUMIF($C$4:$AL$4,1,$C29:$AL29) -> 40000 | AO29: =SUMIF($C$4:$AL$4,2,$C29:$AL29) -> 20000 | AP29: =SUMIF($C$4:$AL$4,3,$C29:$AL29) -> 20000
A30: Insurance | B30: A$ | C30: =CHOOSE(C$4,Inputs!$B$82,Inputs!$B$83,Inputs!$B$84)/12 -> 833.33333 | D30: =CHOOSE(D$4,Inputs!$B$82,Inputs!$B$83,Inputs!$B$84)/12 -> 833.33333 | E30: =CHOOSE(E$4,Inputs!$B$82,Inputs!$B$83,Inputs!$B$84)/12 -> 833.33333 | F30: =CHOOSE(F$4,Inputs!$B$82,Inputs!$B$83,Inputs!$B$84)/12 -> 833.33333 | G30: =CHOOSE(G$4,Inputs!$B$82,Inputs!$B$83,Inputs!$B$84)/12 -> 833.33333 | H30: =CHOOSE(H$4,Inputs!$B$82,Inputs!$B$83,Inputs!$B$84)/12 -> 833.33333 | I30: =CHOOSE(I$4,Inputs!$B$82,Inputs!$B$83,Inputs!$B$84)/12 -> 833.33333 | J30: =CHOOSE(J$4,Inputs!$B$82,Inputs!$B$83,Inputs!$B$84)/12 -> 833.33333 | ... AL30: =CHOOSE(AL$4,Inputs!$B$82,Inputs!$B$83,Inputs!$B$84)/12 -> 3750 | AN30: =SUMIF($C$4:$AL$4,1,$C30:$AL30) -> 10000 | AO30: =SUMIF($C$4:$AL$4,2,$C30:$AL30) -> 30000 | AP30: =SUMIF($C$4:$AL$4,3,$C30:$AL30) -> 45000
A31: Sales and customer success | B31: A$ | C31: =CHOOSE(C$4,Inputs!$B$85,Inputs!$B$86,Inputs!$B$87)/12 -> 3333.3333 | D31: =CHOOSE(D$4,Inputs!$B$85,Inputs!$B$86,Inputs!$B$87)/12 -> 3333.3333 | E31: =CHOOSE(E$4,Inputs!$B$85,Inputs!$B$86,Inputs!$B$87)/12 -> 3333.3333 | F31: =CHOOSE(F$4,Inputs!$B$85,Inputs!$B$86,Inputs!$B$87)/12 -> 3333.3333 | G31: =CHOOSE(G$4,Inputs!$B$85,Inputs!$B$86,Inputs!$B$87)/12 -> 3333.3333 | H31: =CHOOSE(H$4,Inputs!$B$85,Inputs!$B$86,Inputs!$B$87)/12 -> 3333.3333 | I31: =CHOOSE(I$4,Inputs!$B$85,Inputs!$B$86,Inputs!$B$87)/12 -> 3333.3333 | J31: =CHOOSE(J$4,Inputs!$B$85,Inputs!$B$86,Inputs!$B$87)/12 -> 3333.3333 | ... AL31: =CHOOSE(AL$4,Inputs!$B$85,Inputs!$B$86,Inputs!$B$87)/12 -> 12500 | AN31: =SUMIF($C$4:$AL$4,1,$C31:$AL31) -> 40000 | AO31: =SUMIF($C$4:$AL$4,2,$C31:$AL31) -> 80000 | AP31: =SUMIF($C$4:$AL$4,3,$C31:$AL31) -> 150000
A32: Legal, accounting and IP | B32: A$ | C32: =CHOOSE(C$4,Inputs!$B$88,Inputs!$B$89,Inputs!$B$90)/12 -> 2500 | D32: =CHOOSE(D$4,Inputs!$B$88,Inputs!$B$89,Inputs!$B$90)/12 -> 2500 | E32: =CHOOSE(E$4,Inputs!$B$88,Inputs!$B$89,Inputs!$B$90)/12 -> 2500 | F32: =CHOOSE(F$4,Inputs!$B$88,Inputs!$B$89,Inputs!$B$90)/12 -> 2500 | G32: =CHOOSE(G$4,Inputs!$B$88,Inputs!$B$89,Inputs!$B$90)/12 -> 2500 | H32: =CHOOSE(H$4,Inputs!$B$88,Inputs!$B$89,Inputs!$B$90)/12 -> 2500 | I32: =CHOOSE(I$4,Inputs!$B$88,Inputs!$B$89,Inputs!$B$90)/12 -> 2500 | J32: =CHOOSE(J$4,Inputs!$B$88,Inputs!$B$89,Inputs!$B$90)/12 -> 2500 | ... AL32: =CHOOSE(AL$4,Inputs!$B$88,Inputs!$B$89,Inputs!$B$90)/12 -> 5000 | AN32: =SUMIF($C$4:$AL$4,1,$C32:$AL32) -> 30000 | AO32: =SUMIF($C$4:$AL$4,2,$C32:$AL32) -> 40000 | AP32: =SUMIF($C$4:$AL$4,3,$C32:$AL32) -> 60000
A33: Contingency | B33: A$ | C33: =IF(C$4=1,Inputs!$B$91/12,Inputs!$B$92*SUM(C25:C32)) -> 3000 | D33: =IF(D$4=1,Inputs!$B$91/12,Inputs!$B$92*SUM(D25:D32)) -> 3000 | E33: =IF(E$4=1,Inputs!$B$91/12,Inputs!$B$92*SUM(E25:E32)) -> 3000 | F33: =IF(F$4=1,Inputs!$B$91/12,Inputs!$B$92*SUM(F25:F32)) -> 3000 | G33: =IF(G$4=1,Inputs!$B$91/12,Inputs!$B$92*SUM(G25:G32)) -> 3000 | H33: =IF(H$4=1,Inputs!$B$91/12,Inputs!$B$92*SUM(H25:H32)) -> 3000 | I33: =IF(I$4=1,Inputs!$B$91/12,Inputs!$B$92*SUM(I25:I32)) -> 3000 | J33: =IF(J$4=1,Inputs!$B$91/12,Inputs!$B$92*SUM(J25:J32)) -> 3000 | ... AL33: =IF(AL$4=1,Inputs!$B$91/12,Inputs!$B$92*SUM(AL25:AL32)) -> 7897.3917 | AN33: =SUMIF($C$4:$AL$4,1,$C33:$AL33) -> 36000 | AO33: =SUMIF($C$4:$AL$4,2,$C33:$AL33) -> 50420.11 | AP33: =SUMIF($C$4:$AL$4,3,$C33:$AL33) -> 87597.554
A34: Total costs | B34: A$ | C34: =SUM(C25:C33) -> 61800 | D34: =SUM(D25:D33) -> 61800 | E34: =SUM(E25:E33) -> 62100 | F34: =SUM(F25:F33) -> 62100 | G34: =SUM(G25:G33) -> 62100 | H34: =SUM(H25:H33) -> 62100 | I34: =SUM(I25:I33) -> 62247 | J34: =SUM(J25:J33) -> 62392.53 | ... AL34: =SUM(AL25:AL33) -> 165845.23 | AN34: =SUMIF($C$4:$AL$4,1,$C34:$AL34) -> 747748.56 | AO34: =SUMIF($C$4:$AL$4,2,$C34:$AL34) -> 1058822.3 | AP34: =SUMIF($C$4:$AL$4,3,$C34:$AL34) -> 1839548.6
A36: Operating result | B36: A$ | C36: =C20-C34 -> -61800 | D36: =D20-D34 -> -61800 | E36: =E20-E34 -> -62100 | F36: =F20-F34 -> -62100 | G36: =G20-G34 -> -62100 | H36: =H20-H34 -> -55100 | I36: =I20-I34 -> -51817 | J36: =J20-J34 -> -48566.83 | ... AL36: =AL20-AL34 -> 136319.53 | AN36: =SUMIF($C$4:$AL$4,1,$C36:$AL36) -> -624625.88 | AO36: =SUMIF($C$4:$AL$4,2,$C36:$AL36) -> -97145.994 | AP36: =SUMIF($C$4:$AL$4,3,$C36:$AL36) -> 775560.04
A38: Cash
A39: This round | B39: A$ | C39: =IF(C$3=1,Inputs!$B$95,0) -> 750000 | D39: =IF(D$3=1,Inputs!$B$95,0) -> 0 | E39: =IF(E$3=1,Inputs!$B$95,0) -> 0 | F39: =IF(F$3=1,Inputs!$B$95,0) -> 0 | G39: =IF(G$3=1,Inputs!$B$95,0) -> 0 | H39: =IF(H$3=1,Inputs!$B$95,0) -> 0 | I39: =IF(I$3=1,Inputs!$B$95,0) -> 0 | J39: =IF(J$3=1,Inputs!$B$95,0) -> 0 | ... AL39: =IF(AL$3=1,Inputs!$B$95,0) -> 0 | AN39: =SUMIF($C$4:$AL$4,1,$C39:$AL39) -> 750000 | AO39: =SUMIF($C$4:$AL$4,2,$C39:$AL39) -> 0 | AP39: =SUMIF($C$4:$AL$4,3,$C39:$AL39) -> 0
A40: Cash before the seed round, end of month | B40: A$ | C40: =C36+C39 -> 688200 | D40: =C40+D36+D39 -> 626400 | E40: =D40+E36+E39 -> 564300 | F40: =E40+F36+F39 -> 502200 | G40: =F40+G36+G39 -> 440100 | H40: =G40+H36+H39 -> 385000 | I40: =H40+I36+I39 -> 333183 | J40: =I40+J36+J39 -> 284616.17 | K40: =J40+K36+K39 -> 239267.01 | ... AL40: =AK40+AL36+AL39 -> 803788.16 | AN40: =INDEX($C40:$AL40,1,12) -> 125374.12 | AO40: =INDEX($C40:$AL40,1,24) -> 28228.128 | AP40: =INDEX($C40:$AL40,1,36) -> 803788.16
A41: Seed round | B41: A$ | C41: =IF(C$3=Inputs!$B$97,Inputs!$B$96,0) -> 0 | D41: =IF(D$3=Inputs!$B$97,Inputs!$B$96,0) -> 0 | E41: =IF(E$3=Inputs!$B$97,Inputs!$B$96,0) -> 0 | F41: =IF(F$3=Inputs!$B$97,Inputs!$B$96,0) -> 0 | G41: =IF(G$3=Inputs!$B$97,Inputs!$B$96,0) -> 0 | H41: =IF(H$3=Inputs!$B$97,Inputs!$B$96,0) -> 0 | I41: =IF(I$3=Inputs!$B$97,Inputs!$B$96,0) -> 0 | J41: =IF(J$3=Inputs!$B$97,Inputs!$B$96,0) -> 0 | ... AL41: =IF(AL$3=Inputs!$B$97,Inputs!$B$96,0) -> 0 | AN41: =SUMIF($C$4:$AL$4,1,$C41:$AL41) -> 0 | AO41: =SUMIF($C$4:$AL$4,2,$C41:$AL41) -> 3000000 | AP41: =SUMIF($C$4:$AL$4,3,$C41:$AL41) -> 0
A42: Cash after the seed round, end of month | B42: A$ | C42: =C36+C39+C41 -> 688200 | D42: =C42+D36+D39+D41 -> 626400 | E42: =D42+E36+E39+E41 -> 564300 | F42: =E42+F36+F39+F41 -> 502200 | G42: =F42+G36+G39+G41 -> 440100 | H42: =G42+H36+H39+H41 -> 385000 | I42: =H42+I36+I39+I41 -> 333183 | J42: =I42+J36+J39+J41 -> 284616.17 | K42: =J42+K36+K39+K41 -> 239267.01 | ... AL42: =AK42+AL36+AL39+AL41 -> 3803788.2 | AN42: =INDEX($C42:$AL42,1,12) -> 125374.12 | AO42: =INDEX($C42:$AL42,1,24) -> 3028228.1 | AP42: =INDEX($C42:$AL42,1,36) -> 3803788.2
A43: Helper: month if cash before seed is negative | B43: month | C43: =IF(C40<0,C$3,99) -> 99 | D43: =IF(D40<0,D$3,99) -> 99 | E43: =IF(E40<0,E$3,99) -> 99 | F43: =IF(F40<0,F$3,99) -> 99 | G43: =IF(G40<0,G$3,99) -> 99 | H43: =IF(H40<0,H$3,99) -> 99 | I43: =IF(I40<0,I$3,99) -> 99 | J43: =IF(J40<0,J$3,99) -> 99 | ... AL43: =IF(AL40<0,AL$3,99) -> 99

Sheet Conservative
A1: Conservative case: monthly
A2: Monthly drivers, revenue, costs and cash. Formulas only; inputs are on the Inputs sheet. A$.
A3: Month | C3: 1 | D3: =C3+1 -> 2 | E3: =D3+1 -> 3 | F3: =E3+1 -> 4 | G3: =F3+1 -> 5 | H3: =G3+1 -> 6 | I3: =H3+1 -> 7 | J3: =I3+1 -> 8 | K3: =J3+1 -> 9 | ... AL3: =AK3+1 -> 36 | AN3: Year 1 | AO3: Year 2 | AP3: Year 3
A4: Year | C4: =ROUNDUP(C3/12,0) -> 1 | D4: =ROUNDUP(D3/12,0) -> 1 | E4: =ROUNDUP(E3/12,0) -> 1 | F4: =ROUNDUP(F3/12,0) -> 1 | G4: =ROUNDUP(G3/12,0) -> 1 | H4: =ROUNDUP(H3/12,0) -> 1 | I4: =ROUNDUP(I3/12,0) -> 1 | J4: =ROUNDUP(J3/12,0) -> 1 | ... AL4: =ROUNDUP(AL3/12,0) -> 3 | AN4: total or year end | AO4: total or year end | AP4: total or year end
A6: Builder deployments
A7: R&D deployments live (unpaid) | B7: projects | C7: =IF(AND(C$3>=Inputs!$C$42,C$3<Inputs!$C$44),Inputs!$C$43,0) -> 0 | D7: =IF(AND(D$3>=Inputs!$C$42,D$3<Inputs!$C$44),Inputs!$C$43,0) -> 0 | E7: =IF(AND(E$3>=Inputs!$C$42,E$3<Inputs!$C$44),Inputs!$C$43,0) -> 2 | F7: =IF(AND(F$3>=Inputs!$C$42,F$3<Inputs!$C$44),Inputs!$C$43,0) -> 2 | G7: =IF(AND(G$3>=Inputs!$C$42,G$3<Inputs!$C$44),Inputs!$C$43,0) -> 2 | H7: =IF(AND(H$3>=Inputs!$C$42,H$3<Inputs!$C$44),Inputs!$C$43,0) -> 2 | I7: =IF(AND(I$3>=Inputs!$C$42,I$3<Inputs!$C$44),Inputs!$C$43,0) -> 0 | J7: =IF(AND(J$3>=Inputs!$C$42,J$3<Inputs!$C$44),Inputs!$C$43,0) -> 0 | ... AL7: =IF(AND(AL$3>=Inputs!$C$42,AL$3<Inputs!$C$44),Inputs!$C$43,0) -> 0 | AN7: =INDEX($C7:$AL7,1,12) -> 0 | AO7: =INDEX($C7:$AL7,1,24) -> 0 | AP7: =INDEX($C7:$AL7,1,36) -> 0
A8: New paid builder projects | B8: projects | C8: =IF(C$3<=Inputs!$C$44,0,CHOOSE(C$4,Inputs!$C$45,Inputs!$C$46,Inputs!$C$47)) -> 0 | D8: =IF(D$3<=Inputs!$C$44,0,CHOOSE(D$4,Inputs!$C$45,Inputs!$C$46,Inputs!$C$47)) -> 0 | E8: =IF(E$3<=Inputs!$C$44,0,CHOOSE(E$4,Inputs!$C$45,Inputs!$C$46,Inputs!$C$47)) -> 0 | F8: =IF(F$3<=Inputs!$C$44,0,CHOOSE(F$4,Inputs!$C$45,Inputs!$C$46,Inputs!$C$47)) -> 0 | G8: =IF(G$3<=Inputs!$C$44,0,CHOOSE(G$4,Inputs!$C$45,Inputs!$C$46,Inputs!$C$47)) -> 0 | H8: =IF(H$3<=Inputs!$C$44,0,CHOOSE(H$4,Inputs!$C$45,Inputs!$C$46,Inputs!$C$47)) -> 0 | I8: =IF(I$3<=Inputs!$C$44,0,CHOOSE(I$4,Inputs!$C$45,Inputs!$C$46,Inputs!$C$47)) -> 0 | J8: =IF(J$3<=Inputs!$C$44,0,CHOOSE(J$4,Inputs!$C$45,Inputs!$C$46,Inputs!$C$47)) -> 0.5 | ... AL8: =IF(AL$3<=Inputs!$C$44,0,CHOOSE(AL$4,Inputs!$C$45,Inputs!$C$46,Inputs!$C$47)) -> 1 | AN8: =SUMIF($C$4:$AL$4,1,$C8:$AL8) -> 2.5 | AO8: =SUMIF($C$4:$AL$4,2,$C8:$AL8) -> 9 | AP8: =SUMIF($C$4:$AL$4,3,$C8:$AL8) -> 12
A9: Paid builder projects, end of month | B9: projects | C9: =IF(C$3<Inputs!$C$44,0,IF(C$3=Inputs!$C$44,Inputs!$C$43,0*(1-Inputs!$C$48)+C8)) -> 0 | D9: =IF(D$3<Inputs!$C$44,0,IF(D$3=Inputs!$C$44,Inputs!$C$43,C9*(1-Inputs!$C$48)+D8)) -> 0 | E9: =IF(E$3<Inputs!$C$44,0,IF(E$3=Inputs!$C$44,Inputs!$C$43,D9*(1-Inputs!$C$48)+E8)) -> 0 | F9: =IF(F$3<Inputs!$C$44,0,IF(F$3=Inputs!$C$44,Inputs!$C$43,E9*(1-Inputs!$C$48)+F8)) -> 0 | G9: =IF(G$3<Inputs!$C$44,0,IF(G$3=Inputs!$C$44,Inputs!$C$43,F9*(1-Inputs!$C$48)+G8)) -> 0 | H9: =IF(H$3<Inputs!$C$44,0,IF(H$3=Inputs!$C$44,Inputs!$C$43,G9*(1-Inputs!$C$48)+H8)) -> 0 | I9: =IF(I$3<Inputs!$C$44,0,IF(I$3=Inputs!$C$44,Inputs!$C$43,H9*(1-Inputs!$C$48)+I8)) -> 2 | J9: =IF(J$3<Inputs!$C$44,0,IF(J$3=Inputs!$C$44,Inputs!$C$43,I9*(1-Inputs!$C$48)+J8)) -> 2.46 | K9: =IF(K$3<Inputs!$C$44,0,IF(K$3=Inputs!$C$44,Inputs!$C$43,J9*(1-Inputs!$C$48)+K8)) -> 2.9108 | ... AL9: =IF(AL$3<Inputs!$C$44,0,IF(AL$3=Inputs!$C$44,Inputs!$C$43,AK9*(1-Inputs!$C$48)+AL8)) -> 19.691604 | AN9: =INDEX($C9:$AL9,1,12) -> 4.2098217 | AO9: =INDEX($C9:$AL9,1,24) -> 11.37664 | AP9: =INDEX($C9:$AL9,1,36) -> 19.691604
A10: Builder subscription revenue | B10: A$ | C10: =C9*Inputs!$C$35 -> 0 | D10: =D9*Inputs!$C$35 -> 0 | E10: =E9*Inputs!$C$35 -> 0 | F10: =F9*Inputs!$C$35 -> 0 | G10: =G9*Inputs!$C$35 -> 0 | H10: =H9*Inputs!$C$35 -> 0 | I10: =I9*Inputs!$C$35 -> 7000 | J10: =J9*Inputs!$C$35 -> 8610 | ... AL10: =AL9*Inputs!$C$35 -> 68920.613 | AN10: =SUMIF($C$4:$AL$4,1,$C10:$AL10) -> 65515.583 | AO10: =SUMIF($C$4:$AL$4,2,$C10:$AL10) -> 345890.6 | AP10: =SUMIF($C$4:$AL$4,3,$C10:$AL10) -> 673983.78
A12: Lender mandates
A13: Lenders with the condition | B13: lenders | C13: =COUNTIF(Inputs!$C$51:$C$55,"<="&C$3) -> 0 | D13: =COUNTIF(Inputs!$C$51:$C$55,"<="&D$3) -> 0 | E13: =COUNTIF(Inputs!$C$51:$C$55,"<="&E$3) -> 0 | F13: =COUNTIF(Inputs!$C$51:$C$55,"<="&F$3) -> 0 | G13: =COUNTIF(Inputs!$C$51:$C$55,"<="&G$3) -> 0 | H13: =COUNTIF(Inputs!$C$51:$C$55,"<="&H$3) -> 0 | I13: =COUNTIF(Inputs!$C$51:$C$55,"<="&I$3) -> 0 | J13: =COUNTIF(Inputs!$C$51:$C$55,"<="&J$3) -> 0 | ... AL13: =COUNTIF(Inputs!$C$51:$C$55,"<="&AL$3) -> 3 | AN13: =INDEX($C13:$AL13,1,12) -> 0 | AO13: =INDEX($C13:$AL13,1,24) -> 1 | AP13: =INDEX($C13:$AL13,1,36) -> 3
A14: New facilities under the condition | B14: facilities | C14: =C13*Inputs!$C$56 -> 0 | D14: =D13*Inputs!$C$56 -> 0 | E14: =E13*Inputs!$C$56 -> 0 | F14: =F13*Inputs!$C$56 -> 0 | G14: =G13*Inputs!$C$56 -> 0 | H14: =H13*Inputs!$C$56 -> 0 | I14: =I13*Inputs!$C$56 -> 0 | J14: =J13*Inputs!$C$56 -> 0 | ... AL14: =AL13*Inputs!$C$56 -> 1.5 | AN14: =SUMIF($C$4:$AL$4,1,$C14:$AL14) -> 0 | AO14: =SUMIF($C$4:$AL$4,2,$C14:$AL14) -> 3.5 | AP14: =SUMIF($C$4:$AL$4,3,$C14:$AL14) -> 13
A15: Facilities completing | B15: facilities | C15: =IF(C$3>Inputs!$C$57,INDEX($C$14:$AL$14,1,C$3-Inputs!$C$57),0) -> 0 | D15: =IF(D$3>Inputs!$C$57,INDEX($C$14:$AL$14,1,D$3-Inputs!$C$57),0) -> 0 | E15: =IF(E$3>Inputs!$C$57,INDEX($C$14:$AL$14,1,E$3-Inputs!$C$57),0) -> 0 | F15: =IF(F$3>Inputs!$C$57,INDEX($C$14:$AL$14,1,F$3-Inputs!$C$57),0) -> 0 | G15: =IF(G$3>Inputs!$C$57,INDEX($C$14:$AL$14,1,G$3-Inputs!$C$57),0) -> 0 | H15: =IF(H$3>Inputs!$C$57,INDEX($C$14:$AL$14,1,H$3-Inputs!$C$57),0) -> 0 | I15: =IF(I$3>Inputs!$C$57,INDEX($C$14:$AL$14,1,I$3-Inputs!$C$57),0) -> 0 | J15: =IF(J$3>Inputs!$C$57,INDEX($C$14:$AL$14,1,J$3-Inputs!$C$57),0) -> 0 | ... AL15: =IF(AL$3>Inputs!$C$57,INDEX($C$14:$AL$14,1,AL$3-Inputs!$C$57),0) -> 0 | AN15: =SUMIF($C$4:$AL$4,1,$C15:$AL15) -> 0 | AO15: =SUMIF($C$4:$AL$4,2,$C15:$AL15) -> 0 | AP15: =SUMIF($C$4:$AL$4,3,$C15:$AL15) -> 0
A16: Facilities under the condition, end of month | B16: facilities | C16: =C14-C15 -> 0 | D16: =C16+D14-D15 -> 0 | E16: =D16+E14-E15 -> 0 | F16: =E16+F14-F15 -> 0 | G16: =F16+G14-G15 -> 0 | H16: =G16+H14-H15 -> 0 | I16: =H16+I14-I15 -> 0 | J16: =I16+J14-J15 -> 0 | K16: =J16+K14-K15 -> 0 | ... AL16: =AK16+AL14-AL15 -> 16.5 | AN16: =INDEX($C16:$AL16,1,12) -> 0 | AO16: =INDEX($C16:$AL16,1,24) -> 3.5 | AP16: =INDEX($C16:$AL16,1,36) -> 16.5
A17: Fee per facility | B17: A$ a month | C17: =MIN(MAX(Inputs!$C$39*1000000*Inputs!$C$36/10000/12,Inputs!$C$37),Inputs!$C$38) -> 3500 | D17: =MIN(MAX(Inputs!$C$39*1000000*Inputs!$C$36/10000/12,Inputs!$C$37),Inputs!$C$38) -> 3500 | E17: =MIN(MAX(Inputs!$C$39*1000000*Inputs!$C$36/10000/12,Inputs!$C$37),Inputs!$C$38) -> 3500 | F17: =MIN(MAX(Inputs!$C$39*1000000*Inputs!$C$36/10000/12,Inputs!$C$37),Inputs!$C$38) -> 3500 | G17: =MIN(MAX(Inputs!$C$39*1000000*Inputs!$C$36/10000/12,Inputs!$C$37),Inputs!$C$38) -> 3500 | H17: =MIN(MAX(Inputs!$C$39*1000000*Inputs!$C$36/10000/12,Inputs!$C$37),Inputs!$C$38) -> 3500 | I17: =MIN(MAX(Inputs!$C$39*1000000*Inputs!$C$36/10000/12,Inputs!$C$37),Inputs!$C$38) -> 3500 | J17: =MIN(MAX(Inputs!$C$39*1000000*Inputs!$C$36/10000/12,Inputs!$C$37),Inputs!$C$38) -> 3500 | ... AL17: =MIN(MAX(Inputs!$C$39*1000000*Inputs!$C$36/10000/12,Inputs!$C$37),Inputs!$C$38) -> 3500 | AN17: =INDEX($C17:$AL17,1,12) -> 3500 | AO17: =INDEX($C17:$AL17,1,24) -> 3500 | AP17: =INDEX($C17:$AL17,1,36) -> 3500
A18: Facility fee revenue | B18: A$ | C18: =C16*C17 -> 0 | D18: =D16*D17 -> 0 | E18: =E16*E17 -> 0 | F18: =F16*F17 -> 0 | G18: =G16*G17 -> 0 | H18: =H16*H17 -> 0 | I18: =I16*I17 -> 0 | J18: =J16*J17 -> 0 | ... AL18: =AL16*AL17 -> 57750 | AN18: =SUMIF($C$4:$AL$4,1,$C18:$AL18) -> 0 | AO18: =SUMIF($C$4:$AL$4,2,$C18:$AL18) -> 49000 | AP18: =SUMIF($C$4:$AL$4,3,$C18:$AL18) -> 397250
A20: Total revenue | B20: A$ | C20: =C10+C18 -> 0 | D20: =D10+D18 -> 0 | E20: =E10+E18 -> 0 | F20: =F10+F18 -> 0 | G20: =G10+G18 -> 0 | H20: =H10+H18 -> 0 | I20: =I10+I18 -> 7000 | J20: =J10+J18 -> 8610 | ... AL20: =AL10+AL18 -> 126670.61 | AN20: =SUMIF($C$4:$AL$4,1,$C20:$AL20) -> 65515.583 | AO20: =SUMIF($C$4:$AL$4,2,$C20:$AL20) -> 394890.6 | AP20: =SUMIF($C$4:$AL$4,3,$C20:$AL20) -> 1071233.8
A21: Annualised revenue (month × 12) | B21: A$ | C21: =C20*12 -> 0 | D21: =D20*12 -> 0 | E21: =E20*12 -> 0 | F21: =F20*12 -> 0 | G21: =G20*12 -> 0 | H21: =H20*12 -> 0 | I21: =I20*12 -> 84000 | J21: =J20*12 -> 103320 | ... AL21: =AL20*12 -> 1520047.4 | AN21: =INDEX($C21:$AL21,1,12) -> 176812.51 | AO21: =INDEX($C21:$AL21,1,24) -> 624818.89 | AP21: =INDEX($C21:$AL21,1,36) -> 1520047.4
A23: Team and costs
A24: Team, end of month | B24: people | C24: =Inputs!$C$60+COUNTIF(Inputs!$D$66:$D$72,"<="&C$3) -> 2 | D24: =Inputs!$C$60+COUNTIF(Inputs!$D$66:$D$72,"<="&D$3) -> 2 | E24: =Inputs!$C$60+COUNTIF(Inputs!$D$66:$D$72,"<="&E$3) -> 2 | F24: =Inputs!$C$60+COUNTIF(Inputs!$D$66:$D$72,"<="&F$3) -> 2 | G24: =Inputs!$C$60+COUNTIF(Inputs!$D$66:$D$72,"<="&G$3) -> 2 | H24: =Inputs!$C$60+COUNTIF(Inputs!$D$66:$D$72,"<="&H$3) -> 2 | I24: =Inputs!$C$60+COUNTIF(Inputs!$D$66:$D$72,"<="&I$3) -> 2 | J24: =Inputs!$C$60+COUNTIF(Inputs!$D$66:$D$72,"<="&J$3) -> 2 | ... AL24: =Inputs!$C$60+COUNTIF(Inputs!$D$66:$D$72,"<="&AL$3) -> 7 | AN24: =INDEX($C24:$AL24,1,12) -> 2 | AO24: =INDEX($C24:$AL24,1,24) -> 5 | AP24: =INDEX($C24:$AL24,1,36) -> 7
A25: Founders | B25: A$ | C25: =Inputs!$C$60*Inputs!$C$61/12*(1+Inputs!$C$62) -> 26133.333 | D25: =Inputs!$C$60*Inputs!$C$61/12*(1+Inputs!$C$62) -> 26133.333 | E25: =Inputs!$C$60*Inputs!$C$61/12*(1+Inputs!$C$62) -> 26133.333 | F25: =Inputs!$C$60*Inputs!$C$61/12*(1+Inputs!$C$62) -> 26133.333 | G25: =Inputs!$C$60*Inputs!$C$61/12*(1+Inputs!$C$62) -> 26133.333 | H25: =Inputs!$C$60*Inputs!$C$61/12*(1+Inputs!$C$62) -> 26133.333 | I25: =Inputs!$C$60*Inputs!$C$61/12*(1+Inputs!$C$62) -> 26133.333 | J25: =Inputs!$C$60*Inputs!$C$61/12*(1+Inputs!$C$62) -> 26133.333 | ... AL25: =Inputs!$C$60*Inputs!$C$61/12*(1+Inputs!$C$62) -> 26133.333 | AN25: =SUMIF($C$4:$AL$4,1,$C25:$AL25) -> 313600 | AO25: =SUMIF($C$4:$AL$4,2,$C25:$AL25) -> 313600 | AP25: =SUMIF($C$4:$AL$4,3,$C25:$AL25) -> 313600
A26: Hires | B26: A$ | C26: =SUMPRODUCT((Inputs!$D$66:$D$72<=C$3)*Inputs!$B$66:$B$72)/12*(1+Inputs!$C$62) -> 0 | D26: =SUMPRODUCT((Inputs!$D$66:$D$72<=D$3)*Inputs!$B$66:$B$72)/12*(1+Inputs!$C$62) -> 0 | E26: =SUMPRODUCT((Inputs!$D$66:$D$72<=E$3)*Inputs!$B$66:$B$72)/12*(1+Inputs!$C$62) -> 0 | F26: =SUMPRODUCT((Inputs!$D$66:$D$72<=F$3)*Inputs!$B$66:$B$72)/12*(1+Inputs!$C$62) -> 0 | G26: =SUMPRODUCT((Inputs!$D$66:$D$72<=G$3)*Inputs!$B$66:$B$72)/12*(1+Inputs!$C$62) -> 0 | H26: =SUMPRODUCT((Inputs!$D$66:$D$72<=H$3)*Inputs!$B$66:$B$72)/12*(1+Inputs!$C$62) -> 0 | I26: =SUMPRODUCT((Inputs!$D$66:$D$72<=I$3)*Inputs!$B$66:$B$72)/12*(1+Inputs!$C$62) -> 0 | J26: =SUMPRODUCT((Inputs!$D$66:$D$72<=J$3)*Inputs!$B$66:$B$72)/12*(1+Inputs!$C$62) -> 0 | ... AL26: =SUMPRODUCT((Inputs!$D$66:$D$72<=AL$3)*Inputs!$B$66:$B$72)/12*(1+Inputs!$C$62) -> 66266.667 | AN26: =SUMIF($C$4:$AL$4,1,$C26:$AL26) -> 0 | AO26: =SUMIF($C$4:$AL$4,2,$C26:$AL26) -> 215600 | AP26: =SUMIF($C$4:$AL$4,3,$C26:$AL26) -> 688800
A27: Platform build and contract engineering | B27: A$ | C27: =CHOOSE(C$4,Inputs!$C$75,Inputs!$C$76,Inputs!$C$77)/12 -> 21666.667 | D27: =CHOOSE(D$4,Inputs!$C$75,Inputs!$C$76,Inputs!$C$77)/12 -> 21666.667 | E27: =CHOOSE(E$4,Inputs!$C$75,Inputs!$C$76,Inputs!$C$77)/12 -> 21666.667 | F27: =CHOOSE(F$4,Inputs!$C$75,Inputs!$C$76,Inputs!$C$77)/12 -> 21666.667 | G27: =CHOOSE(G$4,Inputs!$C$75,Inputs!$C$76,Inputs!$C$77)/12 -> 21666.667 | H27: =CHOOSE(H$4,Inputs!$C$75,Inputs!$C$76,Inputs!$C$77)/12 -> 21666.667 | I27: =CHOOSE(I$4,Inputs!$C$75,Inputs!$C$76,Inputs!$C$77)/12 -> 21666.667 | J27: =CHOOSE(J$4,Inputs!$C$75,Inputs!$C$76,Inputs!$C$77)/12 -> 21666.667 | ... AL27: =CHOOSE(AL$4,Inputs!$C$75,Inputs!$C$76,Inputs!$C$77)/12 -> 3333.3333 | AN27: =SUMIF($C$4:$AL$4,1,$C27:$AL27) -> 260000 | AO27: =SUMIF($C$4:$AL$4,2,$C27:$AL27) -> 40000 | AP27: =SUMIF($C$4:$AL$4,3,$C27:$AL27) -> 40000
A28: Cloud, models and tools | B28: A$ | C28: =Inputs!$C$78+(C7+C9+C16)*Inputs!$C$79 -> 1000 | D28: =Inputs!$C$78+(D7+D9+D16)*Inputs!$C$79 -> 1000 | E28: =Inputs!$C$78+(E7+E9+E16)*Inputs!$C$79 -> 1400 | F28: =Inputs!$C$78+(F7+F9+F16)*Inputs!$C$79 -> 1400 | G28: =Inputs!$C$78+(G7+G9+G16)*Inputs!$C$79 -> 1400 | H28: =Inputs!$C$78+(H7+H9+H16)*Inputs!$C$79 -> 1400 | I28: =Inputs!$C$78+(I7+I9+I16)*Inputs!$C$79 -> 1400 | J28: =Inputs!$C$78+(J7+J9+J16)*Inputs!$C$79 -> 1492 | ... AL28: =Inputs!$C$78+(AL7+AL9+AL16)*Inputs!$C$79 -> 8238.3207 | AN28: =SUMIF($C$4:$AL$4,1,$C28:$AL28) -> 17343.748 | AO28: =SUMIF($C$4:$AL$4,2,$C28:$AL28) -> 34565.177 | AP28: =SUMIF($C$4:$AL$4,3,$C28:$AL28) -> 73213.359
A29: Security certification and audits | B29: A$ | C29: =CHOOSE(C$4,Inputs!$C$80,Inputs!$C$81,Inputs!$C$81)/12 -> 3333.3333 | D29: =CHOOSE(D$4,Inputs!$C$80,Inputs!$C$81,Inputs!$C$81)/12 -> 3333.3333 | E29: =CHOOSE(E$4,Inputs!$C$80,Inputs!$C$81,Inputs!$C$81)/12 -> 3333.3333 | F29: =CHOOSE(F$4,Inputs!$C$80,Inputs!$C$81,Inputs!$C$81)/12 -> 3333.3333 | G29: =CHOOSE(G$4,Inputs!$C$80,Inputs!$C$81,Inputs!$C$81)/12 -> 3333.3333 | H29: =CHOOSE(H$4,Inputs!$C$80,Inputs!$C$81,Inputs!$C$81)/12 -> 3333.3333 | I29: =CHOOSE(I$4,Inputs!$C$80,Inputs!$C$81,Inputs!$C$81)/12 -> 3333.3333 | J29: =CHOOSE(J$4,Inputs!$C$80,Inputs!$C$81,Inputs!$C$81)/12 -> 3333.3333 | ... AL29: =CHOOSE(AL$4,Inputs!$C$80,Inputs!$C$81,Inputs!$C$81)/12 -> 1666.6667 | AN29: =SUMIF($C$4:$AL$4,1,$C29:$AL29) -> 40000 | AO29: =SUMIF($C$4:$AL$4,2,$C29:$AL29) -> 20000 | AP29: =SUMIF($C$4:$AL$4,3,$C29:$AL29) -> 20000
A30: Insurance | B30: A$ | C30: =CHOOSE(C$4,Inputs!$C$82,Inputs!$C$83,Inputs!$C$84)/12 -> 833.33333 | D30: =CHOOSE(D$4,Inputs!$C$82,Inputs!$C$83,Inputs!$C$84)/12 -> 833.33333 | E30: =CHOOSE(E$4,Inputs!$C$82,Inputs!$C$83,Inputs!$C$84)/12 -> 833.33333 | F30: =CHOOSE(F$4,Inputs!$C$82,Inputs!$C$83,Inputs!$C$84)/12 -> 833.33333 | G30: =CHOOSE(G$4,Inputs!$C$82,Inputs!$C$83,Inputs!$C$84)/12 -> 833.33333 | H30: =CHOOSE(H$4,Inputs!$C$82,Inputs!$C$83,Inputs!$C$84)/12 -> 833.33333 | I30: =CHOOSE(I$4,Inputs!$C$82,Inputs!$C$83,Inputs!$C$84)/12 -> 833.33333 | J30: =CHOOSE(J$4,Inputs!$C$82,Inputs!$C$83,Inputs!$C$84)/12 -> 833.33333 | ... AL30: =CHOOSE(AL$4,Inputs!$C$82,Inputs!$C$83,Inputs!$C$84)/12 -> 3750 | AN30: =SUMIF($C$4:$AL$4,1,$C30:$AL30) -> 10000 | AO30: =SUMIF($C$4:$AL$4,2,$C30:$AL30) -> 30000 | AP30: =SUMIF($C$4:$AL$4,3,$C30:$AL30) -> 45000
A31: Sales and customer success | B31: A$ | C31: =CHOOSE(C$4,Inputs!$C$85,Inputs!$C$86,Inputs!$C$87)/12 -> 3333.3333 | D31: =CHOOSE(D$4,Inputs!$C$85,Inputs!$C$86,Inputs!$C$87)/12 -> 3333.3333 | E31: =CHOOSE(E$4,Inputs!$C$85,Inputs!$C$86,Inputs!$C$87)/12 -> 3333.3333 | F31: =CHOOSE(F$4,Inputs!$C$85,Inputs!$C$86,Inputs!$C$87)/12 -> 3333.3333 | G31: =CHOOSE(G$4,Inputs!$C$85,Inputs!$C$86,Inputs!$C$87)/12 -> 3333.3333 | H31: =CHOOSE(H$4,Inputs!$C$85,Inputs!$C$86,Inputs!$C$87)/12 -> 3333.3333 | I31: =CHOOSE(I$4,Inputs!$C$85,Inputs!$C$86,Inputs!$C$87)/12 -> 3333.3333 | J31: =CHOOSE(J$4,Inputs!$C$85,Inputs!$C$86,Inputs!$C$87)/12 -> 3333.3333 | ... AL31: =CHOOSE(AL$4,Inputs!$C$85,Inputs!$C$86,Inputs!$C$87)/12 -> 8333.3333 | AN31: =SUMIF($C$4:$AL$4,1,$C31:$AL31) -> 40000 | AO31: =SUMIF($C$4:$AL$4,2,$C31:$AL31) -> 60000 | AP31: =SUMIF($C$4:$AL$4,3,$C31:$AL31) -> 100000
A32: Legal, accounting and IP | B32: A$ | C32: =CHOOSE(C$4,Inputs!$C$88,Inputs!$C$89,Inputs!$C$90)/12 -> 2500 | D32: =CHOOSE(D$4,Inputs!$C$88,Inputs!$C$89,Inputs!$C$90)/12 -> 2500 | E32: =CHOOSE(E$4,Inputs!$C$88,Inputs!$C$89,Inputs!$C$90)/12 -> 2500 | F32: =CHOOSE(F$4,Inputs!$C$88,Inputs!$C$89,Inputs!$C$90)/12 -> 2500 | G32: =CHOOSE(G$4,Inputs!$C$88,Inputs!$C$89,Inputs!$C$90)/12 -> 2500 | H32: =CHOOSE(H$4,Inputs!$C$88,Inputs!$C$89,Inputs!$C$90)/12 -> 2500 | I32: =CHOOSE(I$4,Inputs!$C$88,Inputs!$C$89,Inputs!$C$90)/12 -> 2500 | J32: =CHOOSE(J$4,Inputs!$C$88,Inputs!$C$89,Inputs!$C$90)/12 -> 2500 | ... AL32: =CHOOSE(AL$4,Inputs!$C$88,Inputs!$C$89,Inputs!$C$90)/12 -> 5000 | AN32: =SUMIF($C$4:$AL$4,1,$C32:$AL32) -> 30000 | AO32: =SUMIF($C$4:$AL$4,2,$C32:$AL32) -> 40000 | AP32: =SUMIF($C$4:$AL$4,3,$C32:$AL32) -> 60000
A33: Contingency | B33: A$ | C33: =IF(C$4=1,Inputs!$C$91/12,Inputs!$C$92*SUM(C25:C32)) -> 3000 | D33: =IF(D$4=1,Inputs!$C$91/12,Inputs!$C$92*SUM(D25:D32)) -> 3000 | E33: =IF(E$4=1,Inputs!$C$91/12,Inputs!$C$92*SUM(E25:E32)) -> 3000 | F33: =IF(F$4=1,Inputs!$C$91/12,Inputs!$C$92*SUM(F25:F32)) -> 3000 | G33: =IF(G$4=1,Inputs!$C$91/12,Inputs!$C$92*SUM(G25:G32)) -> 3000 | H33: =IF(H$4=1,Inputs!$C$91/12,Inputs!$C$92*SUM(H25:H32)) -> 3000 | I33: =IF(I$4=1,Inputs!$C$91/12,Inputs!$C$92*SUM(I25:I32)) -> 3000 | J33: =IF(J$4=1,Inputs!$C$91/12,Inputs!$C$92*SUM(J25:J32)) -> 3000 | ... AL33: =IF(AL$4=1,Inputs!$C$91/12,Inputs!$C$92*SUM(AL25:AL32)) -> 6136.0827 | AN33: =SUMIF($C$4:$AL$4,1,$C33:$AL33) -> 36000 | AO33: =SUMIF($C$4:$AL$4,2,$C33:$AL33) -> 37688.259 | AP33: =SUMIF($C$4:$AL$4,3,$C33:$AL33) -> 67030.668
A34: Total costs | B34: A$ | C34: =SUM(C25:C33) -> 61800 | D34: =SUM(D25:D33) -> 61800 | E34: =SUM(E25:E33) -> 62200 | F34: =SUM(F25:F33) -> 62200 | G34: =SUM(G25:G33) -> 62200 | H34: =SUM(H25:H33) -> 62200 | I34: =SUM(I25:I33) -> 62200 | J34: =SUM(J25:J33) -> 62292 | ... AL34: =SUM(AL25:AL33) -> 128857.74 | AN34: =SUMIF($C$4:$AL$4,1,$C34:$AL34) -> 746943.75 | AO34: =SUMIF($C$4:$AL$4,2,$C34:$AL34) -> 791453.44 | AP34: =SUMIF($C$4:$AL$4,3,$C34:$AL34) -> 1407644
A36: Operating result | B36: A$ | C36: =C20-C34 -> -61800 | D36: =D20-D34 -> -61800 | E36: =E20-E34 -> -62200 | F36: =F20-F34 -> -62200 | G36: =G20-G34 -> -62200 | H36: =H20-H34 -> -62200 | I36: =I20-I34 -> -55200 | J36: =J20-J34 -> -53682 | ... AL36: =AL20-AL34 -> -2187.1237 | AN36: =SUMIF($C$4:$AL$4,1,$C36:$AL36) -> -681428.16 | AO36: =SUMIF($C$4:$AL$4,2,$C36:$AL36) -> -396562.84 | AP36: =SUMIF($C$4:$AL$4,3,$C36:$AL36) -> -336410.25
A38: Cash
A39: This round | B39: A$ | C39: =IF(C$3=1,Inputs!$C$95,0) -> 750000 | D39: =IF(D$3=1,Inputs!$C$95,0) -> 0 | E39: =IF(E$3=1,Inputs!$C$95,0) -> 0 | F39: =IF(F$3=1,Inputs!$C$95,0) -> 0 | G39: =IF(G$3=1,Inputs!$C$95,0) -> 0 | H39: =IF(H$3=1,Inputs!$C$95,0) -> 0 | I39: =IF(I$3=1,Inputs!$C$95,0) -> 0 | J39: =IF(J$3=1,Inputs!$C$95,0) -> 0 | ... AL39: =IF(AL$3=1,Inputs!$C$95,0) -> 0 | AN39: =SUMIF($C$4:$AL$4,1,$C39:$AL39) -> 750000 | AO39: =SUMIF($C$4:$AL$4,2,$C39:$AL39) -> 0 | AP39: =SUMIF($C$4:$AL$4,3,$C39:$AL39) -> 0
A40: Cash before the seed round, end of month | B40: A$ | C40: =C36+C39 -> 688200 | D40: =C40+D36+D39 -> 626400 | E40: =D40+E36+E39 -> 564200 | F40: =E40+F36+F39 -> 502000 | G40: =F40+G36+G39 -> 439800 | H40: =G40+H36+H39 -> 377600 | I40: =H40+I36+I39 -> 322400 | J40: =I40+J36+J39 -> 268718 | K40: =J40+K36+K39 -> 216523.64 | ... AL40: =AK40+AL36+AL39 -> -664401.25 | AN40: =INDEX($C40:$AL40,1,12) -> 68571.835 | AO40: =INDEX($C40:$AL40,1,24) -> -327991 | AP40: =INDEX($C40:$AL40,1,36) -> -664401.25
A41: Seed round | B41: A$ | C41: =IF(C$3=Inputs!$C$97,Inputs!$C$96,0) -> 0 | D41: =IF(D$3=Inputs!$C$97,Inputs!$C$96,0) -> 0 | E41: =IF(E$3=Inputs!$C$97,Inputs!$C$96,0) -> 0 | F41: =IF(F$3=Inputs!$C$97,Inputs!$C$96,0) -> 0 | G41: =IF(G$3=Inputs!$C$97,Inputs!$C$96,0) -> 0 | H41: =IF(H$3=Inputs!$C$97,Inputs!$C$96,0) -> 0 | I41: =IF(I$3=Inputs!$C$97,Inputs!$C$96,0) -> 0 | J41: =IF(J$3=Inputs!$C$97,Inputs!$C$96,0) -> 0 | ... AL41: =IF(AL$3=Inputs!$C$97,Inputs!$C$96,0) -> 0 | AN41: =SUMIF($C$4:$AL$4,1,$C41:$AL41) -> 0 | AO41: =SUMIF($C$4:$AL$4,2,$C41:$AL41) -> 3000000 | AP41: =SUMIF($C$4:$AL$4,3,$C41:$AL41) -> 0
A42: Cash after the seed round, end of month | B42: A$ | C42: =C36+C39+C41 -> 688200 | D42: =C42+D36+D39+D41 -> 626400 | E42: =D42+E36+E39+E41 -> 564200 | F42: =E42+F36+F39+F41 -> 502000 | G42: =F42+G36+G39+G41 -> 439800 | H42: =G42+H36+H39+H41 -> 377600 | I42: =H42+I36+I39+I41 -> 322400 | J42: =I42+J36+J39+J41 -> 268718 | K42: =J42+K36+K39+K41 -> 216523.64 | ... AL42: =AK42+AL36+AL39+AL41 -> 2335598.7 | AN42: =INDEX($C42:$AL42,1,12) -> 68571.835 | AO42: =INDEX($C42:$AL42,1,24) -> 2672009 | AP42: =INDEX($C42:$AL42,1,36) -> 2335598.7
